Workbook

Sheet Puntajes
A1: Fecha | B1: Se | C1: Mb | D1: Na | E1: Ra | F1: ²H | G1: Ganador/es
A2: 1 | B2: 28 | C2: 28 | D2: 25 | E2: 23 | F2: 25 | G2: =IFERROR(__xludf.DUMMYFUNCTION("JOIN("","", FILTER(B$1:F$1, B2:F2 = MAX(B2:F2)))"),"Se,Mb") -> Se,Mb
A3: =A2+1 -> 2 | B3: 19 | C3: 28 | D3: 21 | E3: 23 | F3: 19 | G3: =IFERROR(__xludf.DUMMYFUNCTION("JOIN("","", FILTER(B$1:F$1, B3:F3 = MAX(B3:F3)))"),"Mb") -> Mb
A4: =A3+1 -> 3 | B4: 25 | C4: 28 | D4: 22 | E4: 24 | F4: 21 | G4: =IFERROR(__xludf.DUMMYFUNCTION("JOIN("","", FILTER(B$1:F$1, B4:F4 = MAX(B4:F4)))"),"Mb") -> Mb
A5: =A4+1 -> 4 | B5: 21 | C5: 19 | D5: 20 | E5: 17 | F5: 25 | G5: =IFERROR(__xludf.DUMMYFUNCTION("JOIN("","", FILTER(B$1:F$1, B5:F5 = MAX(B5:F5)))"),"²H") -> ²H
A6: =A5+1 -> 5 | B6: 28 | C6: 28 | D6: 22 | E6: 19 | F6: 25 | G6: =IFERROR(__xludf.DUMMYFUNCTION("JOIN("","", FILTER(B$1:F$1, B6:F6 = MAX(B6:F6)))"),"Se,Mb") -> Se,Mb
A7: =A6+1 -> 6 | B7: 21 | C7: 21 | D7: 17 | E7: 19 | F7: 22 | G7: =IFERROR(__xludf.DUMMYFUNCTION("JOIN("","", FILTER(B$1:F$1, B7:F7 = MAX(B7:F7)))"),"²H") -> ²H
A8: =A7+1 -> 7 | B8: 25 | C8: 25 | D8: 21 | E8: 22 | F8: 21 | G8: =IFERROR(__xludf.DUMMYFUNCTION("JOIN("","", FILTER(B$1:F$1, B8:F8 = MAX(B8:F8)))"),"Se,Mb") -> Se,Mb
A9: =A8+1 -> 8 | B9: 22 | C9: 22 | D9: 22 | E9: 11 | F9: 25 | G9: =IFERROR(__xludf.DUMMYFUNCTION("JOIN("","", FILTER(B$1:F$1, B9:F9 = MAX(B9:F9)))"),"²H") -> ²H
A10: =A9+1 -> 9 | B10: 22 | C10: 21 | D10: 19 | E10: 22 | F10: 22 | G10: =IFERROR(__xludf.DUMMYFUNCTION("JOIN("","", FILTER(B$1:F$1, B10:F10 = MAX(B10:F10)))"),"Se,Ra,²H") -> Se,Ra,²H
A11: =A10+1 -> 10 | B11: 25 | C11: 25 | D11: 19 | E11: 17 | F11: 22 | G11: =IFERROR(__xludf.DUMMYFUNCTION("JOIN("","", FILTER(B$1:F$1, B11:F11 = MAX(B11:F11)))"),"Se,Mb") -> Se,Mb
A12: =A11+1 -> 11 | B12: 25 | C12: 25 | D12: 19 | E12: 21 | F12: 25 | G12: =IFERROR(__xludf.DUMMYFUNCTION("JOIN("","", FILTER(B$1:F$1, B12:F12 = MAX(B12:F12)))"),"Se,Mb,²H") -> Se,Mb,²H
A13: =A12+1 -> 12 | B13: 25 | C13: 25 | D13: 20 | E13: 19 | F13: 20 | G13: =IFERROR(__xludf.DUMMYFUNCTION("JOIN("","", FILTER(B$1:F$1, B13:F13 = MAX(B13:F13)))"),"Se,Mb") -> Se,Mb
A14: =A13+1 -> 13 | B14: 25 | C14: 20 | D14: 22 | E14: 22 | F14: 28 | G14: =IFERROR(__xludf.DUMMYFUNCTION("JOIN("","", FILTER(B$1:F$1, B14:F14 = MAX(B14:F14)))"),"²H") -> ²H
A15: 14 | B15: 25 | C15: 22 | D15: 22 | E15: 18 | F15: 25 | G15: =IFERROR(__xludf.DUMMYFUNCTION("JOIN("","", FILTER(B$1:F$1, B15:F15 = MAX(B15:F15)))"),"Se,²H") -> Se,²H
A16: 15 | B16: 19 | C16: 20 | D16: 17 | E16: 25 | F16: 18 | G16: =IFERROR(__xludf.DUMMYFUNCTION("JOIN("","", FILTER(B$1:F$1, B16:F16 = MAX(B16:F16)))"),"Ra") -> Ra
A17: =A16+1 -> 16 | B17: 25 | C17: 25 | D17: 23 | E17: 23 | G17: =IFERROR(__xludf.DUMMYFUNCTION("JOIN("","", FILTER(B$1:F$1, B17:F17 = MAX(B17:F17)))"),"Se,Mb") -> Se,Mb
A18: =A17+1 -> 17 | B18: 28 | C18: 22 | D18: 21 | E18: 25 | G18: =IFERROR(__xludf.DUMMYFUNCTION("JOIN("","", FILTER(B$1:F$1, B18:F18 = MAX(B18:F18)))"),"Se") -> Se
A19: =A18+1 -> 18 | B19: 22 | C19: 20 | D19: 20 | E19: 22 | G19: =IFERROR(__xludf.DUMMYFUNCTION("JOIN("","", FILTER(B$1:F$1, B19:F19 = MAX(B19:F19)))"),"Se,Ra") -> Se,Ra
A20: =A19+1 -> 19 | B20: 25 | C20: 22 | D20: 19 | E20: 24 | F20: 28 | G20: =IFERROR(__xludf.DUMMYFUNCTION("JOIN("","", FILTER(B$1:F$1, B20:F20 = MAX(B20:F20)))"),"²H") -> ²H
A21: =A20+1 -> 20 | B21: 24 | C21: 21 | D21: 25 | E21: 22 | G21: =IFERROR(__xludf.DUMMYFUNCTION("JOIN("","", FILTER(B$1:F$1, B21:F21 = MAX(B21:F21)))"),"Na") -> Na
A22: =A21+1 -> 21 | B22: 21 | C22: 19 | D22: 26 | E22: 22 | G22: =IFERROR(__xludf.DUMMYFUNCTION("JOIN("","", FILTER(B$1:F$1, B22:F22 = MAX(B22:F22)))"),"Na") -> Na
A23: 22 | B23: 21 | C23: 28 | D23: 24 | E23: 21 | F23: 28 | G23: =IFERROR(__xludf.DUMMYFUNCTION("JOIN("","", FILTER(B$1:F$1, B23:F23 = MAX(B23:F23)))"),"Mb,²H") -> Mb,²H
A24: =A23+1 -> 23 | B24: 17 | C24: 25 | D24: 15 | E24: 23 | F24: 25 | G24: =IFERROR(__xludf.DUMMYFUNCTION("JOIN("","", FILTER(B$1:F$1, B24:F24 = MAX(B24:F24)))"),"Mb,²H") -> Mb,²H
A25: =A24+1 -> 24 | B25: 28 | C25: 22 | D25: 16 | E25: 25 | G25: =IFERROR(__xludf.DUMMYFUNCTION("JOIN("","", FILTER(B$1:F$1, B25:F25 = MAX(B25:F25)))"),"Se") -> Se
A26: =A25+1 -> 25 | B26: 25 | C26: 28 | D26: 25 | E26: 25 | G26: =IFERROR(__xludf.DUMMYFUNCTION("JOIN("","", FILTER(B$1:F$1, B26:F26 = MAX(B26:F26)))"),"Mb") -> Mb
A27: =A26+1 -> 26 | B27: 25 | C27: 28 | D27: 19 | E27: 15 | F27: 23 | G27: =IFERROR(__xludf.DUMMYFUNCTION("JOIN("","", FILTER(B$1:F$1, B27:F27 = MAX(B27:F27)))"),"Mb") -> Mb
A28: =A27+1 -> 27 | B28: 28 | C28: 28 | D28: 15 | E28: 19 | F28: 25 | G28: =IFERROR(__xludf.DUMMYFUNCTION("JOIN("","", FILTER(B$1:F$1, B28:F28 = MAX(B28:F28)))"),"Se,Mb") -> Se,Mb
A29: =A28+1 -> 28 | B29: 25 | C29: 22 | E29: 24 | G29: =IFERROR(__xludf.DUMMYFUNCTION("JOIN("","", FILTER(B$1:F$1, B29:F29 = MAX(B29:F29)))"),"Se") -> Se
A30: =A29+1 -> 29 | B30: 25 | C30: 22 | E30: 17 | F30: 24 | G30: =IFERROR(__xludf.DUMMYFUNCTION("JOIN("","", FILTER(B$1:F$1, B30:F30 = MAX(B30:F30)))"),"Se") -> Se
A31: =A30+1 -> 30 | B31: 22 | C31: 21 | E31: 20 | F31: 25 | G31: =IFERROR(__xludf.DUMMYFUNCTION("JOIN("","", FILTER(B$1:F$1, B31:F31 = MAX(B31:F31)))"),"²H") -> ²H
A32: =A31+1 -> 31 | B32: 22 | C32: 25 | E32: 19 | F32: 22 | G32: =IFERROR(__xludf.DUMMYFUNCTION("JOIN("","", FILTER(B$1:F$1, B32:F32 = MAX(B32:F32)))"),"Mb") -> Mb
A33: =A32+1 -> 32 | B33: 25 | C33: 24 | E33: 26 | F33: 25 | G33: =IFERROR(__xludf.DUMMYFUNCTION("JOIN("","", FILTER(B$1:F$1, B33:F33 = MAX(B33:F33)))"),"Ra") -> Ra
A34: =A33+1 -> 33 | B34: 18 | C34: 21 | F34: 22 | G34: =IFERROR(__xludf.DUMMYFUNCTION("JOIN("","", FILTER(B$1:F$1, B34:F34 = MAX(B34:F34)))"),"²H") -> ²H
A35: =A34+1 -> 34 | B35: 22 | E35: 20 | G35: =IFERROR(__xludf.DUMMYFUNCTION("JOIN("","", FILTER(B$1:F$1, B35:F35 = MAX(B35:F35)))"),"Se") -> Se
A36: =A35+1 -> 35 | G36: =IFERROR(__xludf.DUMMYFUNCTION("JOIN("","", FILTER(B$1:F$1, B36:F36 = MAX(B36:F36)))"),"Se,Mb,Na,Ra,²H") -> Se,Mb,Na,Ra,²H
A37: =A36+1 -> 36 | G37: =IFERROR(__xludf.DUMMYFUNCTION("JOIN("","", FILTER(B$1:F$1, B37:F37 = MAX(B37:F37)))"),"Se,Mb,Na,Ra,²H") -> Se,Mb,Na,Ra,²H
A38: =A37+1 -> 37 | G38: =IFERROR(__xludf.DUMMYFUNCTION("JOIN("","", FILTER(B$1:F$1, B38:F38 = MAX(B38:F38)))"),"Se,Mb,Na,Ra,²H") -> Se,Mb,Na,Ra,²H
A39: =A38+1 -> 38 | G39: =IFERROR(__xludf.DUMMYFUNCTION("JOIN("","", FILTER(B$1:F$1, B39:F39 = MAX(B39:F39)))"),"Se,Mb,Na,Ra,²H") -> Se,Mb,Na,Ra,²H
A40: =A39+1 -> 39 | G40: =IFERROR(__xludf.DUMMYFUNCTION("JOIN("","", FILTER(B$1:F$1, B40:F40 = MAX(B40:F40)))"),"Se,Mb,Na,Ra,²H") -> Se,Mb,Na,Ra,²H
...

Sheet Puntajes2025
A1: Fecha | B1: Se | C1: Mb | D1: Na | E1: Ra | F1: ²H | G1: Ganador/es
A2: 1 | B2: 24 | C2: 16 | D2: 21 | E2: 22 | F2: 24 | G2: =IFERROR(__xludf.DUMMYFUNCTION("JOIN("","", FILTER(B$1:F$1, B2:F2 = MAX(B2:F2)))"),"Se,²H") -> Se,²H
A3: =A2+1 -> 2 | B3: 22 | C3: 24 | D3: 15 | E3: 22 | F3: 21 | G3: =IFERROR(__xludf.DUMMYFUNCTION("JOIN("","", FILTER(B$1:F$1, B3:F3 = MAX(B3:F3)))"),"Mb") -> Mb
A4: =A3+1 -> 3 | B4: 23 | C4: 16 | D4: 12 | E4: 13 | F4: 25 | G4: =IFERROR(__xludf.DUMMYFUNCTION("JOIN("","", FILTER(B$1:F$1, B4:F4 = MAX(B4:F4)))"),"²H") -> ²H
A5: =A4+1 -> 4 | B5: 25 | C5: 23 | D5: 25 | E5: 14 | F5: 25 | G5: =IFERROR(__xludf.DUMMYFUNCTION("JOIN("","", FILTER(B$1:F$1, B5:F5 = MAX(B5:F5)))"),"Se,Na,²H") -> Se,Na,²H
A6: =A5+1 -> 5 | B6: 28 | C6: 17 | D6: 21 | E6: 25 | F6: 25 | G6: =IFERROR(__xludf.DUMMYFUNCTION("JOIN("","", FILTER(B$1:F$1, B6:F6 = MAX(B6:F6)))"),"Se") -> Se
A7: =A6+1 -> 6 | B7: 25 | C7: 26 | D7: 23 | E7: 26 | F7: 20 | G7: =IFERROR(__xludf.DUMMYFUNCTION("JOIN("","", FILTER(B$1:F$1, B7:F7 = MAX(B7:F7)))"),"Mb,Ra") -> Mb,Ra
A8: =A7+1 -> 7 | B8: 21 | C8: 25 | D8: 24 | E8: 28 | F8: 21 | G8: =IFERROR(__xludf.DUMMYFUNCTION("JOIN("","", FILTER(B$1:F$1, B8:F8 = MAX(B8:F8)))"),"Ra") -> Ra
A9: =A8+1 -> 8 | B9: 28 | C9: 26 | D9: 24 | E9: 17 | F9: 20 | G9: =IFERROR(__xludf.DUMMYFUNCTION("JOIN("","", FILTER(B$1:F$1, B9:F9 = MAX(B9:F9)))"),"Se") -> Se
A10: =A9+1 -> 9 | B10: 24 | C10: 16 | D10: 25 | E10: 16 | F10: 28 | G10: =IFERROR(__xludf.DUMMYFUNCTION("JOIN("","", FILTER(B$1:F$1, B10:F10 = MAX(B10:F10)))"),"²H") -> ²H
A11: =A10+1 -> 10 | B11: 25 | C11: 25 | D11: 14 | E11: 22 | F11: 21 | G11: =IFERROR(__xludf.DUMMYFUNCTION("JOIN("","", FILTER(B$1:F$1, B11:F11 = MAX(B11:F11)))"),"Se,Mb") -> Se,Mb
A12: =A11+1 -> 11 | B12: 25 | C12: 19 | D12: 25 | E12: 26 | F12: 19 | G12: =IFERROR(__xludf.DUMMYFUNCTION("JOIN("","", FILTER(B$1:F$1, B12:F12 = MAX(B12:F12)))"),"Ra") -> Ra
A13: =A12+1 -> 12 | B13: 21 | C13: 26 | D13: 15 | E13: 17 | F13: 21 | G13: =IFERROR(__xludf.DUMMYFUNCTION("JOIN("","", FILTER(B$1:F$1, B13:F13 = MAX(B13:F13)))"),"Mb") -> Mb
A14: =A13+1 -> 13 | B14: 25 | C14: 23 | D14: 14 | E14: 17 | F14: 28 | G14: =IFERROR(__xludf.DUMMYFUNCTION("JOIN("","", FILTER(B$1:F$1, B14:F14 = MAX(B14:F14)))"),"²H") -> ²H
A15: 14 | B15: 28 | C15: 25 | D15: 23 | E15: 25 | F15: 19 | G15: =IFERROR(__xludf.DUMMYFUNCTION("JOIN("","", FILTER(B$1:F$1, B15:F15 = MAX(B15:F15)))"),"Se") -> Se
A16: 15 | B16: 28 | C16: 28 | D16: 19 | E16: 23 | F16: 25 | G16: =IFERROR(__xludf.DUMMYFUNCTION("JOIN("","", FILTER(B$1:F$1, B16:F16 = MAX(B16:F16)))"),"Se,Mb") -> Se,Mb
A17: =A16+1 -> 16 | B17: 22 | C17: 18 | D17: 18 | E17: 18 | F17: 22 | G17: =IFERROR(__xludf.DUMMYFUNCTION("JOIN("","", FILTER(B$1:F$1, B17:F17 = MAX(B17:F17)))"),"Se,²H") -> Se,²H
A18: =A17+1 -> 17 | B18: 21 | C18: 22 | D18: 21 | E18: 24 | F18: 28 | G18: =IFERROR(__xludf.DUMMYFUNCTION("JOIN("","", FILTER(B$1:F$1, B18:F18 = MAX(B18:F18)))"),"²H") -> ²H
A19: =A18+1 -> 18 | B19: 28 | C19: 22 | D19: 20 | E19: 20 | F19: 25 | G19: =IFERROR(__xludf.DUMMYFUNCTION("JOIN("","", FILTER(B$1:F$1, B19:F19 = MAX(B19:F19)))"),"Se") -> Se

Sheet Tabla
A1: +-------+-------+-------+-------+-------+------+------------+ | Fecha | Se | Mb | Na | Ra | ²H | Ganador/es | +-------+-------+-------+-------+-------+------+------------+ | 1 | 28 | 28 | 25 | 23 | 25 | Se,Mb | | 2 | 19 | 28 | 21 | 23 | 19 | Mb | | 3 | 25 | 28 | 22 | 24 | 21 | Mb | | 4 | 21 | 19 | 20 | 17 | 25 | ²H | | 5 | 28 | 28 | 22 | 19 | 25 | Se,Mb | | 6 | 21 | 21 | 17 | 19 | 22 | ²H | | 7 | 25 | 25 | 21 | 22 | 21 | Se,Mb | | 8 | 22 | 22 | 22 | 11 | 25 | ²H | | 9 | 22 | 21 | 19 | 22 | 22 | Se,Ra,²H | | 10 | 25 | 25 | 19 | 17 | 22 | Se,Mb | | 11 | 25 | 25 | 19 | 21 | 25 | Se,Mb,²H | | 12 | 25 | 25 | 20 | 19 | 20 | Se,Mb | | 13 | 25 | 20 | 22 | 22 | 28 | ²H | | 14 | 25 | 22 | 22 | 18 | 25 | Se,²H | | 15 | 19 | 20 | 17 | 25 | 18 | Ra | | 16 | 25 | 25 | 23 | 23 | 0 | Se,Mb | | 17 | 28 | 22 | 21 | 25 | 0 | Se | | 18 | 22 | 20 | 20 | 22 | 0 | Se,Ra | | 19 | 25 | 22 | 19 | 24 | 28 | ²H | | 20 | 24 | 21 | 25 | 22 | 0 | Na | | 21 | 21 | 19 | 26 | 22 | 0 | Na | | 22 | 21 | 28 | 24 | 21 | 28 | Mb,²H | | 23 | 17 | 25 | 15 | 23 | 25 | Mb,²H | | 24 | 28 | 22 | 16 | 25 | 0 | Se | | 25 | 25 | 28 | 25 | 25 | 0 | Mb | | 26 | 25 | 28 | 19 | 15 | 23 | Mb | | 27 | 28 | 28 | 15 | 19 | 25 | Se,Mb | | 28 | 25 | 22 | 0 | 24 | 0 | Se | | 29 | 25 | 22 | 0 | 17 | 24 | Se | | 30 | 22 | 21 | 0 | 20 | 25 | ²H | | 31 | 22 | 25 | 0 | 19 | 22 | Mb | | 32 | 25 | 24 | 0 | 26 | 25 | Ra | | 33 | 18 | 21 | 0 | 0 | 22 | ²H | | 34 | 22 | 0 | 0 | 20 | 0 | Se | +-------+-------+-------+-------+-------+------+------------+ | Sum | 803 | 780 | 556 | 694 | 590 | | | Avg | 23.62 | 23.64 | 20.59 | 21.03 | 23.6 | | +-------+-------+-------+-------+-------+------+------------+ +---------+-----------+ | Jugador | Victorias | +---------+-----------+ | Se | 16 | | Mb | 15 | | ²H | 12 | | Ra | 4 | | Na | 2 | +---------+-----------+ | B1: * **Mb**: * https://www.nytimes.com/interactive/2026/08/21/upshot/flashback.html * **Na**: * https://www.nytimes.com/interactive/2026/07/10/upshot/flashback.html * https://www.nytimes.com/interactive/2026/07/17/upshot/flashback.html * https://www.nytimes.com/interactive/2026/07/24/upshot/flashback.html * https://www.nytimes.com/interactive/2026/07/31/upshot/flashback.html * https://www.nytimes.com/interactive/2026/08/07/upshot/flashback.html * https://www.nytimes.com/interactive/2026/08/14/upshot/flashback.html * https://www.nytimes.com/interactive/2026/08/21/upshot/flashback.html * **Ra**: * https://www.nytimes.com/interactive/2026/08/14/upshot/flashback.html * **²H**: * https://www.nytimes.com/interactive/2026/04/17/upshot/flashback.html * https://www.nytimes.com/interactive/2026/04/24/upshot/flashback.html * https://www.nytimes.com/interactive/2026/05/01/upshot/flashback.html * https://www.nytimes.com/interactive/2026/05/15/upshot/flashback.html * https://www.nytimes.com/interactive/2026/05/22/upshot/flashback.html * https://www.nytimes.com/interactive/2026/06/12/upshot/flashback.html * https://www.nytimes.com/interactive/2026/06/19/upshot/flashback.html * https://www.nytimes.com/interactive/2026/07/10/upshot/flashback.html * https://www.nytimes.com/interactive/2026/08/21/upshot/flashback.html

Sheet Missing Se
A1: Fecha | B1: Missing Se | C1: URL | D1: Missing URL
A2: =A3-7 -> 46024 | B2: =IF(AND(Puntajes!B2=0,SUM(Puntajes!B2:F2)>0),1,0) -> 0 | C2: =CONCATENATE("https://www.nytimes.com/interactive/", YEAR(A2), "/", TEXT(MONTH(A2), "00"), "/", TEXT(DAY(A2), "00"), "/upshot/flashback.html") -> https://www.nytimes.com/interactive/2026/01/02/upshot/flashback.html | D2: =IF(B2=1,C2,"")
A3: =A4-7 -> 46031 | B3: =IF(AND(Puntajes!B3=0,SUM(Puntajes!B3:F3)>0),1,0) -> 0 | C3: =CONCATENATE("https://www.nytimes.com/interactive/", YEAR(A3), "/", TEXT(MONTH(A3), "00"), "/", TEXT(DAY(A3), "00"), "/upshot/flashback.html") -> https://www.nytimes.com/interactive/2026/01/09/upshot/flashback.html | D3: =IF(B3=1,C3,"")
A4: =A5-7 -> 46038 | B4: =IF(AND(Puntajes!B4=0,SUM(Puntajes!B4:F4)>0),1,0) -> 0 | C4: =CONCATENATE("https://www.nytimes.com/interactive/", YEAR(A4), "/", TEXT(MONTH(A4), "00"), "/", TEXT(DAY(A4), "00"), "/upshot/flashback.html") -> https://www.nytimes.com/interactive/2026/01/16/upshot/flashback.html | D4: =IF(B4=1,C4,"")
A5: =A6-7 -> 46045 | B5: =IF(AND(Puntajes!B5=0,SUM(Puntajes!B5:F5)>0),1,0) -> 0 | C5: =CONCATENATE("https://www.nytimes.com/interactive/", YEAR(A5), "/", TEXT(MONTH(A5), "00"), "/", TEXT(DAY(A5), "00"), "/upshot/flashback.html") -> https://www.nytimes.com/interactive/2026/01/23/upshot/flashback.html | D5: =IF(B5=1,C5,"")
A6: =A7-7 -> 46052 | B6: =IF(AND(Puntajes!B6=0,SUM(Puntajes!B6:F6)>0),1,0) -> 0 | C6: =CONCATENATE("https://www.nytimes.com/interactive/", YEAR(A6), "/", TEXT(MONTH(A6), "00"), "/", TEXT(DAY(A6), "00"), "/upshot/flashback.html") -> https://www.nytimes.com/interactive/2026/01/30/upshot/flashback.html | D6: =IF(B6=1,C6,"")
A7: =A8-7 -> 46059 | B7: =IF(AND(Puntajes!B7=0,SUM(Puntajes!B7:F7)>0),1,0) -> 0 | C7: =CONCATENATE("https://www.nytimes.com/interactive/", YEAR(A7), "/", TEXT(MONTH(A7), "00"), "/", TEXT(DAY(A7), "00"), "/upshot/flashback.html") -> https://www.nytimes.com/interactive/2026/02/06/upshot/flashback.html | D7: =IF(B7=1,C7,"")
A8: =A9-7 -> 46066 | B8: =IF(AND(Puntajes!B8=0,SUM(Puntajes!B8:F8)>0),1,0) -> 0 | C8: =CONCATENATE("https://www.nytimes.com/interactive/", YEAR(A8), "/", TEXT(MONTH(A8), "00"), "/", TEXT(DAY(A8), "00"), "/upshot/flashback.html") -> https://www.nytimes.com/interactive/2026/02/13/upshot/flashback.html | D8: =IF(B8=1,C8,"")
A9: =A10-7 -> 46073 | B9: =IF(AND(Puntajes!B9=0,SUM(Puntajes!B9:F9)>0),1,0) -> 0 | C9: =CONCATENATE("https://www.nytimes.com/interactive/", YEAR(A9), "/", TEXT(MONTH(A9), "00"), "/", TEXT(DAY(A9), "00"), "/upshot/flashback.html") -> https://www.nytimes.com/interactive/2026/02/20/upshot/flashback.html | D9: =IF(B9=1,C9,"")
A10: =A11-7 -> 46080 | B10: =IF(AND(Puntajes!B10=0,SUM(Puntajes!B10:F10)>0),1,0) -> 0 | C10: =CONCATENATE("https://www.nytimes.com/interactive/", YEAR(A10), "/", TEXT(MONTH(A10), "00"), "/", TEXT(DAY(A10), "00"), "/upshot/flashback.html") -> https://www.nytimes.com/interactive/2026/02/27/upshot/flashback.html | D10: =IF(B10=1,C10,"")
A11: =A12-7 -> 46087 | B11: =IF(AND(Puntajes!B11=0,SUM(Puntajes!B11:F11)>0),1,0) -> 0 | C11: =CONCATENATE("https://www.nytimes.com/interactive/", YEAR(A11), "/", TEXT(MONTH(A11), "00"), "/", TEXT(DAY(A11), "00"), "/upshot/flashback.html") -> https://www.nytimes.com/interactive/2026/03/06/upshot/flashback.html | D11: =IF(B11=1,C11,"")
A12: =A13-7 -> 46094 | B12: =IF(AND(Puntajes!B12=0,SUM(Puntajes!B12:F12)>0),1,0) -> 0 | C12: =CONCATENATE("https://www.nytimes.com/interactive/", YEAR(A12), "/", TEXT(MONTH(A12), "00"), "/", TEXT(DAY(A12), "00"), "/upshot/flashback.html") -> https://www.nytimes.com/interactive/2026/03/13/upshot/flashback.html | D12: =IF(B12=1,C12,"")
A13: =A14-7 -> 46101 | B13: =IF(AND(Puntajes!B13=0,SUM(Puntajes!B13:F13)>0),1,0) -> 0 | C13: =CONCATENATE("https://www.nytimes.com/interactive/", YEAR(A13), "/", TEXT(MONTH(A13), "00"), "/", TEXT(DAY(A13), "00"), "/upshot/flashback.html") -> https://www.nytimes.com/interactive/2026/03/20/upshot/flashback.html | D13: =IF(B13=1,C13,"")
... A23: =A24-7 -> 46171 | B23: =IF(AND(Puntajes!B23=0,SUM(Puntajes!B23:F23)>0),1,0) -> 0 | C23: =CONCATENATE("https://www.nytimes.com/interactive/", YEAR(A23), "/", TEXT(MONTH(A23), "00"), "/", TEXT(DAY(A23), "00"), "/upshot/flashback.html") -> https://www.nytimes.com/interactive/2026/05/29/upshot/flashback.html | D23: =IF(B23=1,C23,"")
A24: 46178 | B24: =IF(AND(Puntajes!B24=0,SUM(Puntajes!B24:F24)>0),1,0) -> 0 | C24: =CONCATENATE("https://www.nytimes.com/interactive/", YEAR(A24), "/", TEXT(MONTH(A24), "00"), "/", TEXT(DAY(A24), "00"), "/upshot/flashback.html") -> https://www.nytimes.com/interactive/2026/06/05/upshot/flashback.html | D24: =IF(B24=1,C24,"")
A25: =A24+7 -> 46185 | B25: =IF(AND(Puntajes!B25=0,SUM(Puntajes!B25:F25)>0),1,0) -> 0 | C25: =CONCATENATE("https://www.nytimes.com/interactive/", YEAR(A25), "/", TEXT(MONTH(A25), "00"), "/", TEXT(DAY(A25), "00"), "/upshot/flashback.html") -> https://www.nytimes.com/interactive/2026/06/12/upshot/flashback.html
A26: =A25+7 -> 46192 | B26: =IF(AND(Puntajes!B26=0,SUM(Puntajes!B26:F26)>0),1,0) -> 0 | C26: =CONCATENATE("https://www.nytimes.com/interactive/", YEAR(A26), "/", TEXT(MONTH(A26), "00"), "/", TEXT(DAY(A26), "00"), "/upshot/flashback.html") -> https://www.nytimes.com/interactive/2026/06/19/upshot/flashback.html
A27: =A26+7 -> 46199 | B27: =IF(AND(Puntajes!B27=0,SUM(Puntajes!B27:F27)>0),1,0) -> 0 | C27: =CONCATENATE("https://www.nytimes.com/interactive/", YEAR(A27), "/", TEXT(MONTH(A27), "00"), "/", TEXT(DAY(A27), "00"), "/upshot/flashback.html") -> https://www.nytimes.com/interactive/2026/06/26/upshot/flashback.html
A28: =A27+7 -> 46206 | B28: =IF(AND(Puntajes!B28=0,SUM(Puntajes!B28:F28)>0),1,0) -> 0 | C28: =CONCATENATE("https://www.nytimes.com/interactive/", YEAR(A28), "/", TEXT(MONTH(A28), "00"), "/", TEXT(DAY(A28), "00"), "/upshot/flashback.html") -> https://www.nytimes.com/interactive/2026/07/03/upshot/flashback.html
A29: =A28+7 -> 46213 | B29: =IF(AND(Puntajes!B29=0,SUM(Puntajes!B29:F29)>0),1,0) -> 0 | C29: =CONCATENATE("https://www.nytimes.com/interactive/", YEAR(A29), "/", TEXT(MONTH(A29), "00"), "/", TEXT(DAY(A29), "00"), "/upshot/flashback.html") -> https://www.nytimes.com/interactive/2026/07/10/upshot/flashback.html
A30: =A29+7 -> 46220 | B30: =IF(AND(Puntajes!B30=0,SUM(Puntajes!B30:F30)>0),1,0) -> 0 | C30: =CONCATENATE("https://www.nytimes.com/interactive/", YEAR(A30), "/", TEXT(MONTH(A30), "00"), "/", TEXT(DAY(A30), "00"), "/upshot/flashback.html") -> https://www.nytimes.com/interactive/2026/07/17/upshot/flashback.html
A31: =A30+7 -> 46227 | B31: =IF(AND(Puntajes!B31=0,SUM(Puntajes!B31:F31)>0),1,0) -> 0 | C31: =CONCATENATE("https://www.nytimes.com/interactive/", YEAR(A31), "/", TEXT(MONTH(A31), "00"), "/", TEXT(DAY(A31), "00"), "/upshot/flashback.html") -> https://www.nytimes.com/interactive/2026/07/24/upshot/flashback.html
A32: =A31+7 -> 46234 | B32: =IF(AND(Puntajes!B32=0,SUM(Puntajes!B32:F32)>0),1,0) -> 0 | C32: =CONCATENATE("https://www.nytimes.com/interactive/", YEAR(A32), "/", TEXT(MONTH(A32), "00"), "/", TEXT(DAY(A32), "00"), "/upshot/flashback.html") -> https://www.nytimes.com/interactive/2026/07/31/upshot/flashback.html
A33: =A32+7 -> 46241 | B33: =IF(AND(Puntajes!B33=0,SUM(Puntajes!B33:F33)>0),1,0) -> 0 | C33: =CONCATENATE("https://www.nytimes.com/interactive/", YEAR(A33), "/", TEXT(MONTH(A33), "00"), "/", TEXT(DAY(A33), "00"), "/upshot/flashback.html") -> https://www.nytimes.com/interactive/2026/08/07/upshot/flashback.html
A34: =A33+7 -> 46248 | B34: =IF(AND(Puntajes!B34=0,SUM(Puntajes!B34:F34)>0),1,0) -> 0 | C34: =CONCATENATE("https://www.nytimes.com/interactive/", YEAR(A34), "/", TEXT(MONTH(A34), "00"), "/", TEXT(DAY(A34), "00"), "/upshot/flashback.html") -> https://www.nytimes.com/interactive/2026/08/14/upshot/flashback.html
A35: =A34+7 -> 46255 | B35: =IF(AND(Puntajes!B35=0,SUM(Puntajes!B35:F35)>0),1,0) -> 0 | C35: =CONCATENATE("https://www.nytimes.com/interactive/", YEAR(A35), "/", TEXT(MONTH(A35), "00"), "/", TEXT(DAY(A35), "00"), "/upshot/flashback.html") -> https://www.nytimes.com/interactive/2026/08/21/upshot/flashback.html
A36: =A35+7 -> 46262 | B36: =IF(AND(Puntajes!B36=0,SUM(Puntajes!B36:F36)>0),1,0) -> 0 | C36: =CONCATENATE("https://www.nytimes.com/interactive/", YEAR(A36), "/", TEXT(MONTH(A36), "00"), "/", TEXT(DAY(A36), "00"), "/upshot/flashback.html") -> https://www.nytimes.com/interactive/2026/08/28/upshot/flashback.html
... A53: =A52+7 -> 46381 | B53: =IF(AND(Puntajes!B53=0,SUM(Puntajes!B53:F53)>0),1,0) -> 0 | C53: =CONCATENATE("https://www.nytimes.com/interactive/", YEAR(A53), "/", TEXT(MONTH(A53), "00"), "/", TEXT(DAY(A53), "00"), "/upshot/flashback.html") -> https://www.nytimes.com/interactive/2026/12/25/upshot/flashback.html

Sheet Missing Mb
A1: Fecha | B1: Missing Mb | C1: URL | D1: Missing URL
A2: 46024 | B2: =IF(AND(Puntajes!C2=0,SUM(Puntajes!B2:F2)>0),1,0) -> 0 | C2: =CONCATENATE("https://www.nytimes.com/interactive/", YEAR(A2), "/", TEXT(MONTH(A2), "00"), "/", TEXT(DAY(A2), "00"), "/upshot/flashback.html") -> https://www.nytimes.com/interactive/2026/01/02/upshot/flashback.html | D2: =IF(B2=1,C2,"")
A3: =A2+7 -> 46031 | B3: =IF(AND(Puntajes!C3=0,SUM(Puntajes!B3:F3)>0),1,0) -> 0 | C3: =CONCATENATE("https://www.nytimes.com/interactive/", YEAR(A3), "/", TEXT(MONTH(A3), "00"), "/", TEXT(DAY(A3), "00"), "/upshot/flashback.html") -> https://www.nytimes.com/interactive/2026/01/09/upshot/flashback.html | D3: =IF(B3=1,C3,"")
A4: =A3+7 -> 46038 | B4: =IF(AND(Puntajes!C4=0,SUM(Puntajes!B4:F4)>0),1,0) -> 0 | C4: =CONCATENATE("https://www.nytimes.com/interactive/", YEAR(A4), "/", TEXT(MONTH(A4), "00"), "/", TEXT(DAY(A4), "00"), "/upshot/flashback.html") -> https://www.nytimes.com/interactive/2026/01/16/upshot/flashback.html | D4: =IF(B4=1,C4,"")
A5: =A4+7 -> 46045 | B5: =IF(AND(Puntajes!C5=0,SUM(Puntajes!B5:F5)>0),1,0) -> 0 | C5: =CONCATENATE("https://www.nytimes.com/interactive/", YEAR(A5), "/", TEXT(MONTH(A5), "00"), "/", TEXT(DAY(A5), "00"), "/upshot/flashback.html") -> https://www.nytimes.com/interactive/2026/01/23/upshot/flashback.html | D5: =IF(B5=1,C5,"")
A6: =A5+7 -> 46052 | B6: =IF(AND(Puntajes!C6=0,SUM(Puntajes!B6:F6)>0),1,0) -> 0 | C6: =CONCATENATE("https://www.nytimes.com/interactive/", YEAR(A6), "/", TEXT(MONTH(A6), "00"), "/", TEXT(DAY(A6), "00"), "/upshot/flashback.html") -> https://www.nytimes.com/interactive/2026/01/30/upshot/flashback.html | D6: =IF(B6=1,C6,"")
A7: =A6+7 -> 46059 | B7: =IF(AND(Puntajes!C7=0,SUM(Puntajes!B7:F7)>0),1,0) -> 0 | C7: =CONCATENATE("https://www.nytimes.com/interactive/", YEAR(A7), "/", TEXT(MONTH(A7), "00"), "/", TEXT(DAY(A7), "00"), "/upshot/flashback.html") -> https://www.nytimes.com/interactive/2026/02/06/upshot/flashback.html | D7: =IF(B7=1,C7,"")
A8: =A7+7 -> 46066 | B8: =IF(AND(Puntajes!C8=0,SUM(Puntajes!B8:F8)>0),1,0) -> 0 | C8: =CONCATENATE("https://www.nytimes.com/interactive/", YEAR(A8), "/", TEXT(MONTH(A8), "00"), "/", TEXT(DAY(A8), "00"), "/upshot/flashback.html") -> https://www.nytimes.com/interactive/2026/02/13/upshot/flashback.html | D8: =IF(B8=1,C8,"")
A9: =A8+7 -> 46073 | B9: =IF(AND(Puntajes!C9=0,SUM(Puntajes!B9:F9)>0),1,0) -> 0 | C9: =CONCATENATE("https://www.nytimes.com/interactive/", YEAR(A9), "/", TEXT(MONTH(A9), "00"), "/", TEXT(DAY(A9), "00"), "/upshot/flashback.html") -> https://www.nytimes.com/interactive/2026/02/20/upshot/flashback.html | D9: =IF(B9=1,C9,"")
A10: =A9+7 -> 46080 | B10: =IF(AND(Puntajes!C10=0,SUM(Puntajes!B10:F10)>0),1,0) -> 0 | C10: =CONCATENATE("https://www.nytimes.com/interactive/", YEAR(A10), "/", TEXT(MONTH(A10), "00"), "/", TEXT(DAY(A10), "00"), "/upshot/flashback.html") -> https://www.nytimes.com/interactive/2026/02/27/upshot/flashback.html | D10: =IF(B10=1,C10,"")
A11: =A10+7 -> 46087 | B11: =IF(AND(Puntajes!C11=0,SUM(Puntajes!B11:F11)>0),1,0) -> 0 | C11: =CONCATENATE("https://www.nytimes.com/interactive/", YEAR(A11), "/", TEXT(MONTH(A11), "00"), "/", TEXT(DAY(A11), "00"), "/upshot/flashback.html") -> https://www.nytimes.com/interactive/2026/03/06/upshot/flashback.html | D11: =IF(B11=1,C11,"")
A12: =A11+7 -> 46094 | B12: =IF(AND(Puntajes!C12=0,SUM(Puntajes!B12:F12)>0),1,0) -> 0 | C12: =CONCATENATE("https://www.nytimes.com/interactive/", YEAR(A12), "/", TEXT(MONTH(A12), "00"), "/", TEXT(DAY(A12), "00"), "/upshot/flashback.html") -> https://www.nytimes.com/interactive/2026/03/13/upshot/flashback.html | D12: =IF(B12=1,C12,"")
A13: =A12+7 -> 46101 | B13: =IF(AND(Puntajes!C13=0,SUM(Puntajes!B13:F13)>0),1,0) -> 0 | C13: =CONCATENATE("https://www.nytimes.com/interactive/", YEAR(A13), "/", TEXT(MONTH(A13), "00"), "/", TEXT(DAY(A13), "00"), "/upshot/flashback.html") -> https://www.nytimes.com/interactive/2026/03/20/upshot/flashback.html | D13: =IF(B13=1,C13,"")
A14: =A13+7 -> 46108 | B14: =IF(AND(Puntajes!C14=0,SUM(Puntajes!B14:F14)>0),1,0) -> 0 | C14: =CONCATENATE("https://www.nytimes.com/interactive/", YEAR(A14), "/", TEXT(MONTH(A14), "00"), "/", TEXT(DAY(A14), "00"), "/upshot/flashback.html") -> https://www.nytimes.com/interactive/2026/03/27/upshot/flashback.html | D14: =IF(B14=1,C14,"")
... A53: =A52+7 -> 46381 | B53: =IF(AND(Puntajes!C53=0,SUM(Puntajes!B53:F53)>0),1,0) -> 0 | C53: =CONCATENATE("https://www.nytimes.com/interactive/", YEAR(A53), "/", TEXT(MONTH(A53), "00"), "/", TEXT(DAY(A53), "00"), "/upshot/flashback.html") -> https://www.nytimes.com/interactive/2026/12/25/upshot/flashback.html | D53: =IF(B53=1,C53,"")

Sheet Missing Na
A1: Fecha | B1: Missing Na | C1: URL | D1: Missing URL
A2: 46024 | B2: =IF(AND(Puntajes!D2=0,SUM(Puntajes!B2:F2)>0),1,0) -> 0 | C2: =CONCATENATE("https://www.nytimes.com/interactive/", YEAR(A2), "/", TEXT(MONTH(A2), "00"), "/", TEXT(DAY(A2), "00"), "/upshot/flashback.html") -> https://www.nytimes.com/interactive/2026/01/02/upshot/flashback.html | D2: =IF(B2=1,C2,"")
A3: =A2+7 -> 46031 | B3: =IF(AND(Puntajes!D3=0,SUM(Puntajes!B3:F3)>0),1,0) -> 0 | C3: =CONCATENATE("https://www.nytimes.com/interactive/", YEAR(A3), "/", TEXT(MONTH(A3), "00"), "/", TEXT(DAY(A3), "00"), "/upshot/flashback.html") -> https://www.nytimes.com/interactive/2026/01/09/upshot/flashback.html | D3: =IF(B3=1,C3,"")
A4: =A3+7 -> 46038 | B4: =IF(AND(Puntajes!D4=0,SUM(Puntajes!B4:F4)>0),1,0) -> 0 | C4: =CONCATENATE("https://www.nytimes.com/interactive/", YEAR(A4), "/", TEXT(MONTH(A4), "00"), "/", TEXT(DAY(A4), "00"), "/upshot/flashback.html") -> https://www.nytimes.com/interactive/2026/01/16/upshot/flashback.html | D4: =IF(B4=1,C4,"")
A5: =A4+7 -> 46045 | B5: =IF(AND(Puntajes!D5=0,SUM(Puntajes!B5:F5)>0),1,0) -> 0 | C5: =CONCATENATE("https://www.nytimes.com/interactive/", YEAR(A5), "/", TEXT(MONTH(A5), "00"), "/", TEXT(DAY(A5), "00"), "/upshot/flashback.html") -> https://www.nytimes.com/interactive/2026/01/23/upshot/flashback.html | D5: =IF(B5=1,C5,"")
A6: =A5+7 -> 46052 | B6: =IF(AND(Puntajes!D6=0,SUM(Puntajes!B6:F6)>0),1,0) -> 0 | C6: =CONCATENATE("https://www.nytimes.com/interactive/", YEAR(A6), "/", TEXT(MONTH(A6), "00"), "/", TEXT(DAY(A6), "00"), "/upshot/flashback.html") -> https://www.nytimes.com/interactive/2026/01/30/upshot/flashback.html | D6: =IF(B6=1,C6,"")
A7: =A6+7 -> 46059 | B7: =IF(AND(Puntajes!D7=0,SUM(Puntajes!B7:F7)>0),1,0) -> 0 | C7: =CONCATENATE("https://www.nytimes.com/interactive/", YEAR(A7), "/", TEXT(MONTH(A7), "00"), "/", TEXT(DAY(A7), "00"), "/upshot/flashback.html") -> https://www.nytimes.com/interactive/2026/02/06/upshot/flashback.html | D7: =IF(B7=1,C7,"")
A8: =A7+7 -> 46066 | B8: =IF(AND(Puntajes!D8=0,SUM(Puntajes!B8:F8)>0),1,0) -> 0 | C8: =CONCATENATE("https://www.nytimes.com/interactive/", YEAR(A8), "/", TEXT(MONTH(A8), "00"), "/", TEXT(DAY(A8), "00"), "/upshot/flashback.html") -> https://www.nytimes.com/interactive/2026/02/13/upshot/flashback.html | D8: =IF(B8=1,C8,"")
A9: =A8+7 -> 46073 | B9: =IF(AND(Puntajes!D9=0,SUM(Puntajes!B9:F9)>0),1,0) -> 0 | C9: =CONCATENATE("https://www.nytimes.com/interactive/", YEAR(A9), "/", TEXT(MONTH(A9), "00"), "/", TEXT(DAY(A9), "00"), "/upshot/flashback.html") -> https://www.nytimes.com/interactive/2026/02/20/upshot/flashback.html | D9: =IF(B9=1,C9,"")
A10: =A9+7 -> 46080 | B10: =IF(AND(Puntajes!D10=0,SUM(Puntajes!B10:F10)>0),1,0) -> 0 | C10: =CONCATENATE("https://www.nytimes.com/interactive/", YEAR(A10), "/", TEXT(MONTH(A10), "00"), "/", TEXT(DAY(A10), "00"), "/upshot/flashback.html") -> https://www.nytimes.com/interactive/2026/02/27/upshot/flashback.html | D10: =IF(B10=1,C10,"")
A11: =A10+7 -> 46087 | B11: =IF(AND(Puntajes!D11=0,SUM(Puntajes!B11:F11)>0),1,0) -> 0 | C11: =CONCATENATE("https://www.nytimes.com/interactive/", YEAR(A11), "/", TEXT(MONTH(A11), "00"), "/", TEXT(DAY(A11), "00"), "/upshot/flashback.html") -> https://www.nytimes.com/interactive/2026/03/06/upshot/flashback.html | D11: =IF(B11=1,C11,"")
A12: =A11+7 -> 46094 | B12: =IF(AND(Puntajes!D12=0,SUM(Puntajes!B12:F12)>0),1,0) -> 0 | C12: =CONCATENATE("https://www.nytimes.com/interactive/", YEAR(A12), "/", TEXT(MONTH(A12), "00"), "/", TEXT(DAY(A12), "00"), "/upshot/flashback.html") -> https://www.nytimes.com/interactive/2026/03/13/upshot/flashback.html | D12: =IF(B12=1,C12,"")
A13: =A12+7 -> 46101 | B13: =IF(AND(Puntajes!D13=0,SUM(Puntajes!B13:F13)>0),1,0) -> 0 | C13: =CONCATENATE("https://www.nytimes.com/interactive/", YEAR(A13), "/", TEXT(MONTH(A13), "00"), "/", TEXT(DAY(A13), "00"), "/upshot/flashback.html") -> https://www.nytimes.com/interactive/2026/03/20/upshot/flashback.html | D13: =IF(B13=1,C13,"")
A14: =A13+7 -> 46108 | B14: =IF(AND(Puntajes!D14=0,SUM(Puntajes!B14:F14)>0),1,0) -> 0 | C14: =CONCATENATE("https://www.nytimes.com/interactive/", YEAR(A14), "/", TEXT(MONTH(A14), "00"), "/", TEXT(DAY(A14), "00"), "/upshot/flashback.html") -> https://www.nytimes.com/interactive/2026/03/27/upshot/flashback.html | D14: =IF(B14=1,C14,"")
... A53: =A52+7 -> 46381 | B53: =IF(AND(Puntajes!D53=0,SUM(Puntajes!B53:F53)>0),1,0) -> 0 | C53: =CONCATENATE("https://www.nytimes.com/interactive/", YEAR(A53), "/", TEXT(MONTH(A53), "00"), "/", TEXT(DAY(A53), "00"), "/upshot/flashback.html") -> https://www.nytimes.com/interactive/2026/12/25/upshot/flashback.html | D53: =IF(B53=1,C53,"")

Sheet Missing Ra
A1: Fecha | B1: Missing Ra | C1: URL | D1: Missing URL
A2: 46024 | B2: =IF(AND(Puntajes!E2=0,SUM(Puntajes!B2:F2)>0),1,0) -> 0 | C2: =CONCATENATE("https://www.nytimes.com/interactive/", YEAR(A2), "/", TEXT(MONTH(A2), "00"), "/", TEXT(DAY(A2), "00"), "/upshot/flashback.html") -> https://www.nytimes.com/interactive/2026/01/02/upshot/flashback.html | D2: =IF(B2=1,C2,"")
A3: =A2+7 -> 46031 | B3: =IF(AND(Puntajes!E3=0,SUM(Puntajes!B3:F3)>0),1,0) -> 0 | C3: =CONCATENATE("https://www.nytimes.com/interactive/", YEAR(A3), "/", TEXT(MONTH(A3), "00"), "/", TEXT(DAY(A3), "00"), "/upshot/flashback.html") -> https://www.nytimes.com/interactive/2026/01/09/upshot/flashback.html | D3: =IF(B3=1,C3,"")
A4: =A3+7 -> 46038 | B4: =IF(AND(Puntajes!E4=0,SUM(Puntajes!B4:F4)>0),1,0) -> 0 | C4: =CONCATENATE("https://www.nytimes.com/interactive/", YEAR(A4), "/", TEXT(MONTH(A4), "00"), "/", TEXT(DAY(A4), "00"), "/upshot/flashback.html") -> https://www.nytimes.com/interactive/2026/01/16/upshot/flashback.html | D4: =IF(B4=1,C4,"")
A5: =A4+7 -> 46045 | B5: =IF(AND(Puntajes!E5=0,SUM(Puntajes!B5:F5)>0),1,0) -> 0 | C5: =CONCATENATE("https://www.nytimes.com/interactive/", YEAR(A5), "/", TEXT(MONTH(A5), "00"), "/", TEXT(DAY(A5), "00"), "/upshot/flashback.html") -> https://www.nytimes.com/interactive/2026/01/23/upshot/flashback.html | D5: =IF(B5=1,C5,"")
A6: =A5+7 -> 46052 | B6: =IF(AND(Puntajes!E6=0,SUM(Puntajes!B6:F6)>0),1,0) -> 0 | C6: =CONCATENATE("https://www.nytimes.com/interactive/", YEAR(A6), "/", TEXT(MONTH(A6), "00"), "/", TEXT(DAY(A6), "00"), "/upshot/flashback.html") -> https://www.nytimes.com/interactive/2026/01/30/upshot/flashback.html | D6: =IF(B6=1,C6,"")
A7: =A6+7 -> 46059 | B7: =IF(AND(Puntajes!E7=0,SUM(Puntajes!B7:F7)>0),1,0) -> 0 | C7: =CONCATENATE("https://www.nytimes.com/interactive/", YEAR(A7), "/", TEXT(MONTH(A7), "00"), "/", TEXT(DAY(A7), "00"), "/upshot/flashback.html") -> https://www.nytimes.com/interactive/2026/02/06/upshot/flashback.html | D7: =IF(B7=1,C7,"")
A8: =A7+7 -> 46066 | B8: =IF(AND(Puntajes!E8=0,SUM(Puntajes!B8:F8)>0),1,0) -> 0 | C8: =CONCATENATE("https://www.nytimes.com/interactive/", YEAR(A8), "/", TEXT(MONTH(A8), "00"), "/", TEXT(DAY(A8), "00"), "/upshot/flashback.html") -> https://www.nytimes.com/interactive/2026/02/13/upshot/flashback.html | D8: =IF(B8=1,C8,"")
A9: =A8+7 -> 46073 | B9: =IF(AND(Puntajes!E9=0,SUM(Puntajes!B9:F9)>0),1,0) -> 0 | C9: =CONCATENATE("https://www.nytimes.com/interactive/", YEAR(A9), "/", TEXT(MONTH(A9), "00"), "/", TEXT(DAY(A9), "00"), "/upshot/flashback.html") -> https://www.nytimes.com/interactive/2026/02/20/upshot/flashback.html | D9: =IF(B9=1,C9,"")
A10: =A9+7 -> 46080 | B10: =IF(AND(Puntajes!E10=0,SUM(Puntajes!B10:F10)>0),1,0) -> 0 | C10: =CONCATENATE("https://www.nytimes.com/interactive/", YEAR(A10), "/", TEXT(MONTH(A10), "00"), "/", TEXT(DAY(A10), "00"), "/upshot/flashback.html") -> https://www.nytimes.com/interactive/2026/02/27/upshot/flashback.html | D10: =IF(B10=1,C10,"")
A11: =A10+7 -> 46087 | B11: =IF(AND(Puntajes!E11=0,SUM(Puntajes!B11:F11)>0),1,0) -> 0 | C11: =CONCATENATE("https://www.nytimes.com/interactive/", YEAR(A11), "/", TEXT(MONTH(A11), "00"), "/", TEXT(DAY(A11), "00"), "/upshot/flashback.html") -> https://www.nytimes.com/interactive/2026/03/06/upshot/flashback.html | D11: =IF(B11=1,C11,"")
A12: =A11+7 -> 46094 | B12: =IF(AND(Puntajes!E12=0,SUM(Puntajes!B12:F12)>0),1,0) -> 0 | C12: =CONCATENATE("https://www.nytimes.com/interactive/", YEAR(A12), "/", TEXT(MONTH(A12), "00"), "/", TEXT(DAY(A12), "00"), "/upshot/flashback.html") -> https://www.nytimes.com/interactive/2026/03/13/upshot/flashback.html | D12: =IF(B12=1,C12,"")
A13: =A12+7 -> 46101 | B13: =IF(AND(Puntajes!E13=0,SUM(Puntajes!B13:F13)>0),1,0) -> 0 | C13: =CONCATENATE("https://www.nytimes.com/interactive/", YEAR(A13), "/", TEXT(MONTH(A13), "00"), "/", TEXT(DAY(A13), "00"), "/upshot/flashback.html") -> https://www.nytimes.com/interactive/2026/03/20/upshot/flashback.html | D13: =IF(B13=1,C13,"")
A14: =A13+7 -> 46108 | B14: =IF(AND(Puntajes!E14=0,SUM(Puntajes!B14:F14)>0),1,0) -> 0 | C14: =CONCATENATE("https://www.nytimes.com/interactive/", YEAR(A14), "/", TEXT(MONTH(A14), "00"), "/", TEXT(DAY(A14), "00"), "/upshot/flashback.html") -> https://www.nytimes.com/interactive/2026/03/27/upshot/flashback.html | D14: =IF(B14=1,C14,"")
... A53: =A52+7 -> 46381 | B53: =IF(AND(Puntajes!E53=0,SUM(Puntajes!B53:F53)>0),1,0) -> 0 | C53: =CONCATENATE("https://www.nytimes.com/interactive/", YEAR(A53), "/", TEXT(MONTH(A53), "00"), "/", TEXT(DAY(A53), "00"), "/upshot/flashback.html") -> https://www.nytimes.com/interactive/2026/12/25/upshot/flashback.html | D53: =IF(B53=1,C53,"")

Sheet Missing ²H
A1: Fecha | B1: Missing ²H | C1: URL | D1: Missing URL
A2: 46024 | B2: =IF(AND(Puntajes!F2=0,SUM(Puntajes!B2:F2)>0),1,0) -> 0 | C2: =CONCATENATE("https://www.nytimes.com/interactive/", YEAR(A2), "/", TEXT(MONTH(A2), "00"), "/", TEXT(DAY(A2), "00"), "/upshot/flashback.html") -> https://www.nytimes.com/interactive/2026/01/02/upshot/flashback.html | D2: =IF(B2=1,C2,"")
A3: =A2+7 -> 46031 | B3: =IF(AND(Puntajes!F3=0,SUM(Puntajes!B3:F3)>0),1,0) -> 0 | C3: =CONCATENATE("https://www.nytimes.com/interactive/", YEAR(A3), "/", TEXT(MONTH(A3), "00"), "/", TEXT(DAY(A3), "00"), "/upshot/flashback.html") -> https://www.nytimes.com/interactive/2026/01/09/upshot/flashback.html | D3: =IF(B3=1,C3,"")
A4: =A3+7 -> 46038 | B4: =IF(AND(Puntajes!F4=0,SUM(Puntajes!B4:F4)>0),1,0) -> 0 | C4: =CONCATENATE("https://www.nytimes.com/interactive/", YEAR(A4), "/", TEXT(MONTH(A4), "00"), "/", TEXT(DAY(A4), "00"), "/upshot/flashback.html") -> https://www.nytimes.com/interactive/2026/01/16/upshot/flashback.html | D4: =IF(B4=1,C4,"")
A5: =A4+7 -> 46045 | B5: =IF(AND(Puntajes!F5=0,SUM(Puntajes!B5:F5)>0),1,0) -> 0 | C5: =CONCATENATE("https://www.nytimes.com/interactive/", YEAR(A5), "/", TEXT(MONTH(A5), "00"), "/", TEXT(DAY(A5), "00"), "/upshot/flashback.html") -> https://www.nytimes.com/interactive/2026/01/23/upshot/flashback.html | D5: =IF(B5=1,C5,"")
A6: =A5+7 -> 46052 | B6: =IF(AND(Puntajes!F6=0,SUM(Puntajes!B6:F6)>0),1,0) -> 0 | C6: =CONCATENATE("https://www.nytimes.com/interactive/", YEAR(A6), "/", TEXT(MONTH(A6), "00"), "/", TEXT(DAY(A6), "00"), "/upshot/flashback.html") -> https://www.nytimes.com/interactive/2026/01/30/upshot/flashback.html | D6: =IF(B6=1,C6,"")
A7: =A6+7 -> 46059 | B7: =IF(AND(Puntajes!F7=0,SUM(Puntajes!B7:F7)>0),1,0) -> 0 | C7: =CONCATENATE("https://www.nytimes.com/interactive/", YEAR(A7), "/", TEXT(MONTH(A7), "00"), "/", TEXT(DAY(A7), "00"), "/upshot/flashback.html") -> https://www.nytimes.com/interactive/2026/02/06/upshot/flashback.html | D7: =IF(B7=1,C7,"")
A8: =A7+7 -> 46066 | B8: =IF(AND(Puntajes!F8=0,SUM(Puntajes!B8:F8)>0),1,0) -> 0 | C8: =CONCATENATE("https://www.nytimes.com/interactive/", YEAR(A8), "/", TEXT(MONTH(A8), "00"), "/", TEXT(DAY(A8), "00"), "/upshot/flashback.html") -> https://www.nytimes.com/interactive/2026/02/13/upshot/flashback.html | D8: =IF(B8=1,C8,"")
A9: =A8+7 -> 46073 | B9: =IF(AND(Puntajes!F9=0,SUM(Puntajes!B9:F9)>0),1,0) -> 0 | C9: =CONCATENATE("https://www.nytimes.com/interactive/", YEAR(A9), "/", TEXT(MONTH(A9), "00"), "/", TEXT(DAY(A9), "00"), "/upshot/flashback.html") -> https://www.nytimes.com/interactive/2026/02/20/upshot/flashback.html | D9: =IF(B9=1,C9,"")
A10: =A9+7 -> 46080 | B10: =IF(AND(Puntajes!F10=0,SUM(Puntajes!B10:F10)>0),1,0) -> 0 | C10: =CONCATENATE("https://www.nytimes.com/interactive/", YEAR(A10), "/", TEXT(MONTH(A10), "00"), "/", TEXT(DAY(A10), "00"), "/upshot/flashback.html") -> https://www.nytimes.com/interactive/2026/02/27/upshot/flashback.html | D10: =IF(B10=1,C10,"")
A11: =A10+7 -> 46087 | B11: =IF(AND(Puntajes!F11=0,SUM(Puntajes!B11:F11)>0),1,0) -> 0 | C11: =CONCATENATE("https://www.nytimes.com/interactive/", YEAR(A11), "/", TEXT(MONTH(A11), "00"), "/", TEXT(DAY(A11), "00"), "/upshot/flashback.html") -> https://www.nytimes.com/interactive/2026/03/06/upshot/flashback.html | D11: =IF(B11=1,C11,"")
A12: =A11+7 -> 46094 | B12: =IF(AND(Puntajes!F12=0,SUM(Puntajes!B12:F12)>0),1,0) -> 0 | C12: =CONCATENATE("https://www.nytimes.com/interactive/", YEAR(A12), "/", TEXT(MONTH(A12), "00"), "/", TEXT(DAY(A12), "00"), "/upshot/flashback.html") -> https://www.nytimes.com/interactive/2026/03/13/upshot/flashback.html | D12: =IF(B12=1,C12,"")
A13: =A12+7 -> 46101 | B13: =IF(AND(Puntajes!F13=0,SUM(Puntajes!B13:F13)>0),1,0) -> 0 | C13: =CONCATENATE("https://www.nytimes.com/interactive/", YEAR(A13), "/", TEXT(MONTH(A13), "00"), "/", TEXT(DAY(A13), "00"), "/upshot/flashback.html") -> https://www.nytimes.com/interactive/2026/03/20/upshot/flashback.html | D13: =IF(B13=1,C13,"")
A14: =A13+7 -> 46108 | B14: =IF(AND(Puntajes!F14=0,SUM(Puntajes!B14:F14)>0),1,0) -> 0 | C14: =CONCATENATE("https://www.nytimes.com/interactive/", YEAR(A14), "/", TEXT(MONTH(A14), "00"), "/", TEXT(DAY(A14), "00"), "/upshot/flashback.html") -> https://www.nytimes.com/interactive/2026/03/27/upshot/flashback.html | D14: =IF(B14=1,C14,"")
... A53: =A52+7 -> 46381 | B53: =IF(AND(Puntajes!F53=0,SUM(Puntajes!B53:F53)>0),1,0) -> 0 | C53: =CONCATENATE("https://www.nytimes.com/interactive/", YEAR(A53), "/", TEXT(MONTH(A53), "00"), "/", TEXT(DAY(A53), "00"), "/upshot/flashback.html") -> https://www.nytimes.com/interactive/2026/12/25/upshot/flashback.html | D53: =IF(B53=1,C53,"")
